[2022-03-17 19:48:27,962] {taskinstance.py:1032} INFO - Dependencies all met for <TaskInstance: data_ingestion_gcs_dag_project.download_dataset_task scheduled__2021-01-01T00:00:00+00:00 [queued]>
[2022-03-17 19:48:27,978] {taskinstance.py:1032} INFO - Dependencies all met for <TaskInstance: data_ingestion_gcs_dag_project.download_dataset_task scheduled__2021-01-01T00:00:00+00:00 [queued]>
[2022-03-17 19:48:27,978] {taskinstance.py:1238} INFO - 
--------------------------------------------------------------------------------
[2022-03-17 19:48:27,978] {taskinstance.py:1239} INFO - Starting attempt 1 of 2
[2022-03-17 19:48:27,978] {taskinstance.py:1240} INFO - 
--------------------------------------------------------------------------------
[2022-03-17 19:48:27,995] {taskinstance.py:1259} INFO - Executing <Task(BashOperator): download_dataset_task> on 2021-01-01 00:00:00+00:00
[2022-03-17 19:48:28,002] {standard_task_runner.py:52} INFO - Started process 687 to run task
[2022-03-17 19:48:28,008] {standard_task_runner.py:76} INFO - Running: ['***', 'tasks', 'run', 'data_ingestion_gcs_dag_project', 'download_dataset_task', 'scheduled__2021-01-01T00:00:00+00:00', '--job-id', '28', '--raw', '--subdir', 'DAGS_FOLDER/data_ingestion_gcs_dag_project.py', '--cfg-path', '/tmp/tmphycw6nl3', '--error-file', '/tmp/tmp73j1pqpx']
[2022-03-17 19:48:28,009] {standard_task_runner.py:77} INFO - Job 28: Subtask download_dataset_task
[2022-03-17 19:48:28,090] {logging_mixin.py:109} INFO - Running <TaskInstance: data_ingestion_gcs_dag_project.download_dataset_task scheduled__2021-01-01T00:00:00+00:00 [running]> on host 06aea6ade097
[2022-03-17 19:48:28,131] {warnings.py:110} WARNING - /home/***/.local/lib/python3.7/site-packages/***/utils/context.py:152: AirflowContextDeprecationWarning: Accessing 'execution_date' from the template is deprecated and will be removed in a future version. Please use 'data_interval_start' or 'logical_date' instead.
  warnings.warn(_create_deprecation_warning(key, self._deprecation_replacements[key]))

[2022-03-17 19:48:28,152] {taskinstance.py:1426} INFO - Exporting the following env vars:
AIRFLOW_CTX_DAG_OWNER=***
AIRFLOW_CTX_DAG_ID=data_ingestion_gcs_dag_project
AIRFLOW_CTX_TASK_ID=download_dataset_task
AIRFLOW_CTX_EXECUTION_DATE=2021-01-01T00:00:00+00:00
AIRFLOW_CTX_DAG_RUN_ID=scheduled__2021-01-01T00:00:00+00:00
[2022-03-17 19:48:28,153] {subprocess.py:62} INFO - Tmp dir root location: 
 /tmp
[2022-03-17 19:48:28,154] {subprocess.py:74} INFO - Running command: ['bash', '-c', 'curl -sSLf https://data.dft.gov.uk/road-accidents-safety-data/dft-road-casualty-statistics-accident-2021.csv > /opt/***/dft-road-casualty-statistics-accident-2021.csv']
[2022-03-17 19:48:28,169] {subprocess.py:85} INFO - Output:
[2022-03-17 19:48:28,225] {subprocess.py:89} INFO - curl: (22) The requested URL returned error: 404
[2022-03-17 19:48:28,227] {subprocess.py:93} INFO - Command exited with return code 22
[2022-03-17 19:48:28,248] {taskinstance.py:1700} ERROR - Task failed with exception
Traceback (most recent call last):
  File "/home/airflow/.local/lib/python3.7/site-packages/airflow/models/taskinstance.py", line 1329, in _run_raw_task
    self._execute_task_with_callbacks(context)
  File "/home/airflow/.local/lib/python3.7/site-packages/airflow/models/taskinstance.py", line 1455, in _execute_task_with_callbacks
    result = self._execute_task(context, self.task)
  File "/home/airflow/.local/lib/python3.7/site-packages/airflow/models/taskinstance.py", line 1511, in _execute_task
    result = execute_callable(context=context)
  File "/home/airflow/.local/lib/python3.7/site-packages/airflow/operators/bash.py", line 188, in execute
    f'Bash command failed. The command returned a non-zero exit code {result.exit_code}.'
airflow.exceptions.AirflowException: Bash command failed. The command returned a non-zero exit code 22.
[2022-03-17 19:48:28,259] {taskinstance.py:1277} INFO - Marking task as UP_FOR_RETRY. dag_id=data_ingestion_gcs_dag_project, task_id=download_dataset_task, execution_date=20210101T000000, start_date=20220317T194827, end_date=20220317T194828
[2022-03-17 19:48:28,282] {standard_task_runner.py:92} ERROR - Failed to execute job 28 for task download_dataset_task
Traceback (most recent call last):
  File "/home/airflow/.local/lib/python3.7/site-packages/airflow/task/task_runner/standard_task_runner.py", line 85, in _start_by_fork
    args.func(args, dag=self.dag)
  File "/home/airflow/.local/lib/python3.7/site-packages/airflow/cli/cli_parser.py", line 48, in command
    return func(*args, **kwargs)
  File "/home/airflow/.local/lib/python3.7/site-packages/airflow/utils/cli.py", line 92, in wrapper
    return f(*args, **kwargs)
  File "/home/airflow/.local/lib/python3.7/site-packages/airflow/cli/commands/task_command.py", line 298, in task_run
    _run_task_by_selected_method(args, dag, ti)
  File "/home/airflow/.local/lib/python3.7/site-packages/airflow/cli/commands/task_command.py", line 107, in _run_task_by_selected_method
    _run_raw_task(args, ti)
  File "/home/airflow/.local/lib/python3.7/site-packages/airflow/cli/commands/task_command.py", line 184, in _run_raw_task
    error_file=args.error_file,
  File "/home/airflow/.local/lib/python3.7/site-packages/airflow/utils/session.py", line 70, in wrapper
    return func(*args, session=session, **kwargs)
  File "/home/airflow/.local/lib/python3.7/site-packages/airflow/models/taskinstance.py", line 1329, in _run_raw_task
    self._execute_task_with_callbacks(context)
  File "/home/airflow/.local/lib/python3.7/site-packages/airflow/models/taskinstance.py", line 1455, in _execute_task_with_callbacks
    result = self._execute_task(context, self.task)
  File "/home/airflow/.local/lib/python3.7/site-packages/airflow/models/taskinstance.py", line 1511, in _execute_task
    result = execute_callable(context=context)
  File "/home/airflow/.local/lib/python3.7/site-packages/airflow/operators/bash.py", line 188, in execute
    f'Bash command failed. The command returned a non-zero exit code {result.exit_code}.'
airflow.exceptions.AirflowException: Bash command failed. The command returned a non-zero exit code 22.
[2022-03-17 19:48:28,303] {local_task_job.py:154} INFO - Task exited with return code 1
[2022-03-17 19:48:28,347] {local_task_job.py:264} INFO - 0 downstream tasks scheduled from follow-on schedule check
[2022-03-20 06:19:11,598] {taskinstance.py:1032} INFO - Dependencies all met for <TaskInstance: data_ingestion_gcs_dag_project.download_dataset_task scheduled__2021-01-01T00:00:00+00:00 [queued]>
[2022-03-20 06:19:11,609] {taskinstance.py:1032} INFO - Dependencies all met for <TaskInstance: data_ingestion_gcs_dag_project.download_dataset_task scheduled__2021-01-01T00:00:00+00:00 [queued]>
[2022-03-20 06:19:11,609] {taskinstance.py:1238} INFO - 
--------------------------------------------------------------------------------
[2022-03-20 06:19:11,610] {taskinstance.py:1239} INFO - Starting attempt 1 of 2
[2022-03-20 06:19:11,610] {taskinstance.py:1240} INFO - 
--------------------------------------------------------------------------------
[2022-03-20 06:19:11,621] {taskinstance.py:1259} INFO - Executing <Task(BashOperator): download_dataset_task> on 2021-01-01 00:00:00+00:00
[2022-03-20 06:19:11,627] {standard_task_runner.py:52} INFO - Started process 442 to run task
[2022-03-20 06:19:11,631] {standard_task_runner.py:76} INFO - Running: ['***', 'tasks', 'run', 'data_ingestion_gcs_dag_project', 'download_dataset_task', 'scheduled__2021-01-01T00:00:00+00:00', '--job-id', '47', '--raw', '--subdir', 'DAGS_FOLDER/data_ingestion_gcs_dag_project.py', '--cfg-path', '/tmp/tmp6sy2mh0u', '--error-file', '/tmp/tmprid3ie3m']
[2022-03-20 06:19:11,632] {standard_task_runner.py:77} INFO - Job 47: Subtask download_dataset_task
[2022-03-20 06:19:11,698] {logging_mixin.py:109} INFO - Running <TaskInstance: data_ingestion_gcs_dag_project.download_dataset_task scheduled__2021-01-01T00:00:00+00:00 [running]> on host 974079c1cd0d
[2022-03-20 06:19:11,739] {warnings.py:110} WARNING - /home/***/.local/lib/python3.7/site-packages/***/utils/context.py:152: AirflowContextDeprecationWarning: Accessing 'execution_date' from the template is deprecated and will be removed in a future version. Please use 'data_interval_start' or 'logical_date' instead.
  warnings.warn(_create_deprecation_warning(key, self._deprecation_replacements[key]))

[2022-03-20 06:19:11,760] {taskinstance.py:1426} INFO - Exporting the following env vars:
AIRFLOW_CTX_DAG_OWNER=***
AIRFLOW_CTX_DAG_ID=data_ingestion_gcs_dag_project
AIRFLOW_CTX_TASK_ID=download_dataset_task
AIRFLOW_CTX_EXECUTION_DATE=2021-01-01T00:00:00+00:00
AIRFLOW_CTX_DAG_RUN_ID=scheduled__2021-01-01T00:00:00+00:00
[2022-03-20 06:19:11,761] {subprocess.py:62} INFO - Tmp dir root location: 
 /tmp
[2022-03-20 06:19:11,762] {subprocess.py:74} INFO - Running command: ['bash', '-c', 'curl -sSLf https://data.dft.gov.uk/road-accidents-safety-data/dft-road-casualty-statistics-accident-2021.csv > /opt/***/dft-road-casualty-statistics-accident-2021.csv']
[2022-03-20 06:19:11,775] {subprocess.py:85} INFO - Output:
[2022-03-20 06:19:11,830] {subprocess.py:89} INFO - curl: (22) The requested URL returned error: 404
[2022-03-20 06:19:11,831] {subprocess.py:93} INFO - Command exited with return code 22
[2022-03-20 06:19:11,846] {taskinstance.py:1700} ERROR - Task failed with exception
Traceback (most recent call last):
  File "/home/airflow/.local/lib/python3.7/site-packages/airflow/models/taskinstance.py", line 1329, in _run_raw_task
    self._execute_task_with_callbacks(context)
  File "/home/airflow/.local/lib/python3.7/site-packages/airflow/models/taskinstance.py", line 1455, in _execute_task_with_callbacks
    result = self._execute_task(context, self.task)
  File "/home/airflow/.local/lib/python3.7/site-packages/airflow/models/taskinstance.py", line 1511, in _execute_task
    result = execute_callable(context=context)
  File "/home/airflow/.local/lib/python3.7/site-packages/airflow/operators/bash.py", line 188, in execute
    f'Bash command failed. The command returned a non-zero exit code {result.exit_code}.'
airflow.exceptions.AirflowException: Bash command failed. The command returned a non-zero exit code 22.
[2022-03-20 06:19:11,853] {taskinstance.py:1277} INFO - Marking task as UP_FOR_RETRY. dag_id=data_ingestion_gcs_dag_project, task_id=download_dataset_task, execution_date=20210101T000000, start_date=20220320T061911, end_date=20220320T061911
[2022-03-20 06:19:11,867] {standard_task_runner.py:92} ERROR - Failed to execute job 47 for task download_dataset_task
Traceback (most recent call last):
  File "/home/airflow/.local/lib/python3.7/site-packages/airflow/task/task_runner/standard_task_runner.py", line 85, in _start_by_fork
    args.func(args, dag=self.dag)
  File "/home/airflow/.local/lib/python3.7/site-packages/airflow/cli/cli_parser.py", line 48, in command
    return func(*args, **kwargs)
  File "/home/airflow/.local/lib/python3.7/site-packages/airflow/utils/cli.py", line 92, in wrapper
    return f(*args, **kwargs)
  File "/home/airflow/.local/lib/python3.7/site-packages/airflow/cli/commands/task_command.py", line 298, in task_run
    _run_task_by_selected_method(args, dag, ti)
  File "/home/airflow/.local/lib/python3.7/site-packages/airflow/cli/commands/task_command.py", line 107, in _run_task_by_selected_method
    _run_raw_task(args, ti)
  File "/home/airflow/.local/lib/python3.7/site-packages/airflow/cli/commands/task_command.py", line 184, in _run_raw_task
    error_file=args.error_file,
  File "/home/airflow/.local/lib/python3.7/site-packages/airflow/utils/session.py", line 70, in wrapper
    return func(*args, session=session, **kwargs)
  File "/home/airflow/.local/lib/python3.7/site-packages/airflow/models/taskinstance.py", line 1329, in _run_raw_task
    self._execute_task_with_callbacks(context)
  File "/home/airflow/.local/lib/python3.7/site-packages/airflow/models/taskinstance.py", line 1455, in _execute_task_with_callbacks
    result = self._execute_task(context, self.task)
  File "/home/airflow/.local/lib/python3.7/site-packages/airflow/models/taskinstance.py", line 1511, in _execute_task
    result = execute_callable(context=context)
  File "/home/airflow/.local/lib/python3.7/site-packages/airflow/operators/bash.py", line 188, in execute
    f'Bash command failed. The command returned a non-zero exit code {result.exit_code}.'
airflow.exceptions.AirflowException: Bash command failed. The command returned a non-zero exit code 22.
[2022-03-20 06:19:11,884] {local_task_job.py:154} INFO - Task exited with return code 1
[2022-03-20 06:19:11,923] {local_task_job.py:264} INFO - 0 downstream tasks scheduled from follow-on schedule check
